Workbook

Sheet Dashboard
A1: N95 Fit Test Tracking — Dashboard
A2: Hospital Infection Control | Auto-updates from department sheets
A4: Total Employees | C4: Valid | E4: Expiring Soon | G4: Expired
A5: =B42 -> 0 | C5: =C42 -> 0 | E5: =D42 -> 0 | G5: =E42 -> 0
A7: Breakdown by Department
A8: Department | B8: Total | C8: Valid | D8: Expiring Soon | E8: Expired
A9: AICU | B9: =COUNTA(AICU!A3:A102) -> 0 | C9: =COUNTIF(AICU!G3:G102,"Valid") -> 0 | D9: =COUNTIF(AICU!G3:G102,"Expiring Soon") -> 0 | E9: =COUNTIF(AICU!G3:G102,"Expired") -> 0
A10: IMCU | B10: =COUNTA(IMCU!A3:A102) -> 0 | C10: =COUNTIF(IMCU!G3:G102,"Valid") -> 0 | D10: =COUNTIF(IMCU!G3:G102,"Expiring Soon") -> 0 | E10: =COUNTIF(IMCU!G3:G102,"Expired") -> 0
A11: CCU | B11: =COUNTA(CCU!A3:A102) -> 0 | C11: =COUNTIF(CCU!G3:G102,"Valid") -> 0 | D11: =COUNTIF(CCU!G3:G102,"Expiring Soon") -> 0 | E11: =COUNTIF(CCU!G3:G102,"Expired") -> 0
A12: CICU | B12: =COUNTA(CICU!A3:A102) -> 0 | C12: =COUNTIF(CICU!G3:G102,"Valid") -> 0 | D12: =COUNTIF(CICU!G3:G102,"Expiring Soon") -> 0 | E12: =COUNTIF(CICU!G3:G102,"Expired") -> 0
A13: SCBU | B13: =COUNTA(SCBU!A3:A102) -> 0 | C13: =COUNTIF(SCBU!G3:G102,"Valid") -> 0 | D13: =COUNTIF(SCBU!G3:G102,"Expiring Soon") -> 0 | E13: =COUNTIF(SCBU!G3:G102,"Expired") -> 0
A14: SICU | B14: =COUNTA(SICU!A3:A102) -> 0 | C14: =COUNTIF(SICU!G3:G102,"Valid") -> 0 | D14: =COUNTIF(SICU!G3:G102,"Expiring Soon") -> 0 | E14: =COUNTIF(SICU!G3:G102,"Expired") -> 0
A15: PICU | B15: =COUNTA(PICU!A3:A102) -> 0 | C15: =COUNTIF(PICU!G3:G102,"Valid") -> 0 | D15: =COUNTIF(PICU!G3:G102,"Expiring Soon") -> 0 | E15: =COUNTIF(PICU!G3:G102,"Expired") -> 0
A16: NICU | B16: =COUNTA(NICU!A3:A102) -> 0 | C16: =COUNTIF(NICU!G3:G102,"Valid") -> 0 | D16: =COUNTIF(NICU!G3:G102,"Expiring Soon") -> 0 | E16: =COUNTIF(NICU!G3:G102,"Expired") -> 0
A17: L&D | B17: =COUNTA('L&D'!A3:A102) -> 0 | C17: =COUNTIF('L&D'!G3:G102,"Valid") -> 0 | D17: =COUNTIF('L&D'!G3:G102,"Expiring Soon") -> 0 | E17: =COUNTIF('L&D'!G3:G102,"Expired") -> 0
A18: OR | B18: =COUNTA(OR!A3:A102) -> 0 | C18: =COUNTIF(OR!G3:G102,"Valid") -> 0 | D18: =COUNTIF(OR!G3:G102,"Expiring Soon") -> 0 | E18: =COUNTIF(OR!G3:G102,"Expired") -> 0
A19: Specialty Clinic | B19: =COUNTA('Specialty Clinic'!A3:A102) -> 0 | C19: =COUNTIF('Specialty Clinic'!G3:G102,"Valid") -> 0 | D19: =COUNTIF('Specialty Clinic'!G3:G102,"Expiring Soon") -> 0 | E19: =COUNTIF('Specialty Clinic'!G3:G102,"Expired") -> 0
A20: Dental | B20: =COUNTA(Dental!A3:A102) -> 0 | C20: =COUNTIF(Dental!G3:G102,"Valid") -> 0 | D20: =COUNTIF(Dental!G3:G102,"Expiring Soon") -> 0 | E20: =COUNTIF(Dental!G3:G102,"Expired") -> 0
A21: FMW | B21: =COUNTA(FMW!A3:A102) -> 0 | C21: =COUNTIF(FMW!G3:G102,"Valid") -> 0 | D21: =COUNTIF(FMW!G3:G102,"Expiring Soon") -> 0 | E21: =COUNTIF(FMW!G3:G102,"Expired") -> 0
A22: OB | B22: =COUNTA(OB!A3:A102) -> 0 | C22: =COUNTIF(OB!G3:G102,"Valid") -> 0 | D22: =COUNTIF(OB!G3:G102,"Expiring Soon") -> 0 | E22: =COUNTIF(OB!G3:G102,"Expired") -> 0
A23: NBN | B23: =COUNTA(NBN!A3:A102) -> 0 | C23: =COUNTIF(NBN!G3:G102,"Valid") -> 0 | D23: =COUNTIF(NBN!G3:G102,"Expiring Soon") -> 0 | E23: =COUNTIF(NBN!G3:G102,"Expired") -> 0
A24: Hemodialysis | B24: =COUNTA(Hemodialysis!A3:A102) -> 0 | C24: =COUNTIF(Hemodialysis!G3:G102,"Valid") -> 0 | D24: =COUNTIF(Hemodialysis!G3:G102,"Expiring Soon") -> 0 | E24: =COUNTIF(Hemodialysis!G3:G102,"Expired") -> 0
A25: Cardiac Center | B25: =COUNTA('Cardiac Center'!A3:A102) -> 0 | C25: =COUNTIF('Cardiac Center'!G3:G102,"Valid") -> 0 | D25: =COUNTIF('Cardiac Center'!G3:G102,"Expiring Soon") -> 0 | E25: =COUNTIF('Cardiac Center'!G3:G102,"Expired") -> 0
A26: PW | B26: =COUNTA(PW!A3:A102) -> 0 | C26: =COUNTIF(PW!G3:G102,"Valid") -> 0 | D26: =COUNTIF(PW!G3:G102,"Expiring Soon") -> 0 | E26: =COUNTIF(PW!G3:G102,"Expired") -> 0
A27: FSW | B27: =COUNTA(FSW!A3:A102) -> 0 | C27: =COUNTIF(FSW!G3:G102,"Valid") -> 0 | D27: =COUNTIF(FSW!G3:G102,"Expiring Soon") -> 0 | E27: =COUNTIF(FSW!G3:G102,"Expired") -> 0
A28: Endoscopy | B28: =COUNTA(Endoscopy!A3:A102) -> 0 | C28: =COUNTIF(Endoscopy!G3:G102,"Valid") -> 0 | D28: =COUNTIF(Endoscopy!G3:G102,"Expiring Soon") -> 0 | E28: =COUNTIF(Endoscopy!G3:G102,"Expired") -> 0
A29: HK | B29: =COUNTA(HK!A3:A102) -> 0 | C29: =COUNTIF(HK!G3:G102,"Valid") -> 0 | D29: =COUNTIF(HK!G3:G102,"Expiring Soon") -> 0 | E29: =COUNTIF(HK!G3:G102,"Expired") -> 0
A30: FMC | B30: =COUNTA(FMC!A3:A102) -> 0 | C30: =COUNTIF(FMC!G3:G102,"Valid") -> 0 | D30: =COUNTIF(FMC!G3:G102,"Expiring Soon") -> 0 | E30: =COUNTIF(FMC!G3:G102,"Expired") -> 0
A31: MMW | B31: =COUNTA(MMW!A3:A102) -> 0 | C31: =COUNTIF(MMW!G3:G102,"Valid") -> 0 | D31: =COUNTIF(MMW!G3:G102,"Expiring Soon") -> 0 | E31: =COUNTIF(MMW!G3:G102,"Expired") -> 0
A32: MSW | B32: =COUNTA(MSW!A3:A102) -> 0 | C32: =COUNTIF(MSW!G3:G102,"Valid") -> 0 | D32: =COUNTIF(MSW!G3:G102,"Expiring Soon") -> 0 | E32: =COUNTIF(MSW!G3:G102,"Expired") -> 0
A33: CW | B33: =COUNTA(CW!A3:A102) -> 0 | C33: =COUNTIF(CW!G3:G102,"Valid") -> 0 | D33: =COUNTIF(CW!G3:G102,"Expiring Soon") -> 0 | E33: =COUNTIF(CW!G3:G102,"Expired") -> 0
A34: Radiology | B34: =COUNTA(Radiology!A3:A102) -> 0 | C34: =COUNTIF(Radiology!G3:G102,"Valid") -> 0 | D34: =COUNTIF(Radiology!G3:G102,"Expiring Soon") -> 0 | E34: =COUNTIF(Radiology!G3:G102,"Expired") -> 0
A35: HHC | B35: =COUNTA(HHC!A3:A102) -> 0 | C35: =COUNTIF(HHC!G3:G102,"Valid") -> 0 | D35: =COUNTIF(HHC!G3:G102,"Expiring Soon") -> 0 | E35: =COUNTIF(HHC!G3:G102,"Expired") -> 0
A36: MS1 | B36: =COUNTA('MS1'!A3:A102) -> 0 | C36: =COUNTIF('MS1'!G3:G102,"Valid") -> 0 | D36: =COUNTIF('MS1'!G3:G102,"Expiring Soon") -> 0 | E36: =COUNTIF('MS1'!G3:G102,"Expired") -> 0
A37: DAY CASE | B37: =COUNTA('DAY CASE'!A3:A102) -> 0 | C37: =COUNTIF('DAY CASE'!G3:G102,"Valid") -> 0 | D37: =COUNTIF('DAY CASE'!G3:G102,"Expiring Soon") -> 0 | E37: =COUNTIF('DAY CASE'!G3:G102,"Expired") -> 0
A38: LABORATORY | B38: =COUNTA(LABORATORY!A3:A102) -> 0 | C38: =COUNTIF(LABORATORY!G3:G102,"Valid") -> 0 | D38: =COUNTIF(LABORATORY!G3:G102,"Expiring Soon") -> 0 | E38: =COUNTIF(LABORATORY!G3:G102,"Expired") -> 0
A39: ER | B39: =COUNTA(ER!A3:A102) -> 0 | C39: =COUNTIF(ER!G3:G102,"Valid") -> 0 | D39: =COUNTIF(ER!G3:G102,"Expiring Soon") -> 0 | E39: =COUNTIF(ER!G3:G102,"Expired") -> 0
A40: RR | B40: =COUNTA(RR!A3:A102) -> 0 | C40: =COUNTIF(RR!G3:G102,"Valid") -> 0 | D40: =COUNTIF(RR!G3:G102,"Expiring Soon") -> 0 | E40: =COUNTIF(RR!G3:G102,"Expired") -> 0
A41: Physiotherapy | B41: =COUNTA(Physiotherapy!A3:A102) -> 0 | C41: =COUNTIF(Physiotherapy!G3:G102,"Valid") -> 0 | D41: =COUNTIF(Physiotherapy!G3:G102,"Expiring Soon") -> 0 | E41: =COUNTIF(Physiotherapy!G3:G102,"Expired") -> 0
A42: TOTAL | B42: =SUM(B9:B41) -> 0 | C42: =SUM(C9:C41) -> 0 | D42: =SUM(D9:D41) -> 0 | E42: =SUM(E9:E41) -> 0
...

Sheet AICU
A1: AICU — N95 Fit Test Tracking
A2: Employee Name | B2: Employee ID | C2: Department Email | D2: N95 Mask Type | E2: Fit Test Date | F2: Expiration Date | G2: Validation Status
F3: =IF(E3="","",EDATE(E3,24)) | G3: =IF(F3="","",IF(F3<TODAY(),"Expired",IF(F3-TODAY()<=30,"Expiring Soon","Valid")))
F4: =IF(E4="","",EDATE(E4,24)) | G4: =IF(F4="","",IF(F4<TODAY(),"Expired",IF(F4-TODAY()<=30,"Expiring Soon","Valid")))
F5: =IF(E5="","",EDATE(E5,24)) | G5: =IF(F5="","",IF(F5<TODAY(),"Expired",IF(F5-TODAY()<=30,"Expiring Soon","Valid")))
F6: =IF(E6="","",EDATE(E6,24)) | G6: =IF(F6="","",IF(F6<TODAY(),"Expired",IF(F6-TODAY()<=30,"Expiring Soon","Valid")))
F7: =IF(E7="","",EDATE(E7,24)) | G7: =IF(F7="","",IF(F7<TODAY(),"Expired",IF(F7-TODAY()<=30,"Expiring Soon","Valid")))
F8: =IF(E8="","",EDATE(E8,24)) | G8: =IF(F8="","",IF(F8<TODAY(),"Expired",IF(F8-TODAY()<=30,"Expiring Soon","Valid")))
F9: =IF(E9="","",EDATE(E9,24)) | G9: =IF(F9="","",IF(F9<TODAY(),"Expired",IF(F9-TODAY()<=30,"Expiring Soon","Valid")))
F10: =IF(E10="","",EDATE(E10,24)) | G10: =IF(F10="","",IF(F10<TODAY(),"Expired",IF(F10-TODAY()<=30,"Expiring Soon","Valid")))
F11: =IF(E11="","",EDATE(E11,24)) | G11: =IF(F11="","",IF(F11<TODAY(),"Expired",IF(F11-TODAY()<=30,"Expiring Soon","Valid")))
F12: =IF(E12="","",EDATE(E12,24)) | G12: =IF(F12="","",IF(F12<TODAY(),"Expired",IF(F12-TODAY()<=30,"Expiring Soon","Valid")))
F13: =IF(E13="","",EDATE(E13,24)) | G13: =IF(F13="","",IF(F13<TODAY(),"Expired",IF(F13-TODAY()<=30,"Expiring Soon","Valid")))
F14: =IF(E14="","",EDATE(E14,24)) | G14: =IF(F14="","",IF(F14<TODAY(),"Expired",IF(F14-TODAY()<=30,"Expiring Soon","Valid")))
... F102: =IF(E102="","",EDATE(E102,24)) | G102: =IF(F102="","",IF(F102<TODAY(),"Expired",IF(F102-TODAY()<=30,"Expiring Soon","Valid")))

Sheet IMCU
A1: IMCU — N95 Fit Test Tracking
A2: Employee Name | B2: Employee ID | C2: Department Email | D2: N95 Mask Type | E2: Fit Test Date | F2: Expiration Date | G2: Validation Status
F3: =IF(E3="","",EDATE(E3,24)) | G3: =IF(F3="","",IF(F3<TODAY(),"Expired",IF(F3-TODAY()<=30,"Expiring Soon","Valid")))
F4: =IF(E4="","",EDATE(E4,24)) | G4: =IF(F4="","",IF(F4<TODAY(),"Expired",IF(F4-TODAY()<=30,"Expiring Soon","Valid")))
F5: =IF(E5="","",EDATE(E5,24)) | G5: =IF(F5="","",IF(F5<TODAY(),"Expired",IF(F5-TODAY()<=30,"Expiring Soon","Valid")))
F6: =IF(E6="","",EDATE(E6,24)) | G6: =IF(F6="","",IF(F6<TODAY(),"Expired",IF(F6-TODAY()<=30,"Expiring Soon","Valid")))
F7: =IF(E7="","",EDATE(E7,24)) | G7: =IF(F7="","",IF(F7<TODAY(),"Expired",IF(F7-TODAY()<=30,"Expiring Soon","Valid")))
F8: =IF(E8="","",EDATE(E8,24)) | G8: =IF(F8="","",IF(F8<TODAY(),"Expired",IF(F8-TODAY()<=30,"Expiring Soon","Valid")))
F9: =IF(E9="","",EDATE(E9,24)) | G9: =IF(F9="","",IF(F9<TODAY(),"Expired",IF(F9-TODAY()<=30,"Expiring Soon","Valid")))
F10: =IF(E10="","",EDATE(E10,24)) | G10: =IF(F10="","",IF(F10<TODAY(),"Expired",IF(F10-TODAY()<=30,"Expiring Soon","Valid")))
F11: =IF(E11="","",EDATE(E11,24)) | G11: =IF(F11="","",IF(F11<TODAY(),"Expired",IF(F11-TODAY()<=30,"Expiring Soon","Valid")))
F12: =IF(E12="","",EDATE(E12,24)) | G12: =IF(F12="","",IF(F12<TODAY(),"Expired",IF(F12-TODAY()<=30,"Expiring Soon","Valid")))
F13: =IF(E13="","",EDATE(E13,24)) | G13: =IF(F13="","",IF(F13<TODAY(),"Expired",IF(F13-TODAY()<=30,"Expiring Soon","Valid")))
F14: =IF(E14="","",EDATE(E14,24)) | G14: =IF(F14="","",IF(F14<TODAY(),"Expired",IF(F14-TODAY()<=30,"Expiring Soon","Valid")))
... F102: =IF(E102="","",EDATE(E102,24)) | G102: =IF(F102="","",IF(F102<TODAY(),"Expired",IF(F102-TODAY()<=30,"Expiring Soon","Valid")))

Sheet CCU
A1: CCU — N95 Fit Test Tracking
A2: Employee Name | B2: Employee ID | C2: Department Email | D2: N95 Mask Type | E2: Fit Test Date | F2: Expiration Date | G2: Validation Status
F3: =IF(E3="","",EDATE(E3,24)) | G3: =IF(F3="","",IF(F3<TODAY(),"Expired",IF(F3-TODAY()<=30,"Expiring Soon","Valid")))
F4: =IF(E4="","",EDATE(E4,24)) | G4: =IF(F4="","",IF(F4<TODAY(),"Expired",IF(F4-TODAY()<=30,"Expiring Soon","Valid")))
F5: =IF(E5="","",EDATE(E5,24)) | G5: =IF(F5="","",IF(F5<TODAY(),"Expired",IF(F5-TODAY()<=30,"Expiring Soon","Valid")))
F6: =IF(E6="","",EDATE(E6,24)) | G6: =IF(F6="","",IF(F6<TODAY(),"Expired",IF(F6-TODAY()<=30,"Expiring Soon","Valid")))
F7: =IF(E7="","",EDATE(E7,24)) | G7: =IF(F7="","",IF(F7<TODAY(),"Expired",IF(F7-TODAY()<=30,"Expiring Soon","Valid")))
F8: =IF(E8="","",EDATE(E8,24)) | G8: =IF(F8="","",IF(F8<TODAY(),"Expired",IF(F8-TODAY()<=30,"Expiring Soon","Valid")))
F9: =IF(E9="","",EDATE(E9,24)) | G9: =IF(F9="","",IF(F9<TODAY(),"Expired",IF(F9-TODAY()<=30,"Expiring Soon","Valid")))
F10: =IF(E10="","",EDATE(E10,24)) | G10: =IF(F10="","",IF(F10<TODAY(),"Expired",IF(F10-TODAY()<=30,"Expiring Soon","Valid")))
F11: =IF(E11="","",EDATE(E11,24)) | G11: =IF(F11="","",IF(F11<TODAY(),"Expired",IF(F11-TODAY()<=30,"Expiring Soon","Valid")))
F12: =IF(E12="","",EDATE(E12,24)) | G12: =IF(F12="","",IF(F12<TODAY(),"Expired",IF(F12-TODAY()<=30,"Expiring Soon","Valid")))
F13: =IF(E13="","",EDATE(E13,24)) | G13: =IF(F13="","",IF(F13<TODAY(),"Expired",IF(F13-TODAY()<=30,"Expiring Soon","Valid")))
F14: =IF(E14="","",EDATE(E14,24)) | G14: =IF(F14="","",IF(F14<TODAY(),"Expired",IF(F14-TODAY()<=30,"Expiring Soon","Valid")))
... F102: =IF(E102="","",EDATE(E102,24)) | G102: =IF(F102="","",IF(F102<TODAY(),"Expired",IF(F102-TODAY()<=30,"Expiring Soon","Valid")))

Sheet CICU
A1: CICU — N95 Fit Test Tracking
A2: Employee Name | B2: Employee ID | C2: Department Email | D2: N95 Mask Type | E2: Fit Test Date | F2: Expiration Date | G2: Validation Status
F3: =IF(E3="","",EDATE(E3,24)) | G3: =IF(F3="","",IF(F3<TODAY(),"Expired",IF(F3-TODAY()<=30,"Expiring Soon","Valid")))
F4: =IF(E4="","",EDATE(E4,24)) | G4: =IF(F4="","",IF(F4<TODAY(),"Expired",IF(F4-TODAY()<=30,"Expiring Soon","Valid")))
F5: =IF(E5="","",EDATE(E5,24)) | G5: =IF(F5="","",IF(F5<TODAY(),"Expired",IF(F5-TODAY()<=30,"Expiring Soon","Valid")))
F6: =IF(E6="","",EDATE(E6,24)) | G6: =IF(F6="","",IF(F6<TODAY(),"Expired",IF(F6-TODAY()<=30,"Expiring Soon","Valid")))
F7: =IF(E7="","",EDATE(E7,24)) | G7: =IF(F7="","",IF(F7<TODAY(),"Expired",IF(F7-TODAY()<=30,"Expiring Soon","Valid")))
F8: =IF(E8="","",EDATE(E8,24)) | G8: =IF(F8="","",IF(F8<TODAY(),"Expired",IF(F8-TODAY()<=30,"Expiring Soon","Valid")))
F9: =IF(E9="","",EDATE(E9,24)) | G9: =IF(F9="","",IF(F9<TODAY(),"Expired",IF(F9-TODAY()<=30,"Expiring Soon","Valid")))
F10: =IF(E10="","",EDATE(E10,24)) | G10: =IF(F10="","",IF(F10<TODAY(),"Expired",IF(F10-TODAY()<=30,"Expiring Soon","Valid")))
F11: =IF(E11="","",EDATE(E11,24)) | G11: =IF(F11="","",IF(F11<TODAY(),"Expired",IF(F11-TODAY()<=30,"Expiring Soon","Valid")))
F12: =IF(E12="","",EDATE(E12,24)) | G12: =IF(F12="","",IF(F12<TODAY(),"Expired",IF(F12-TODAY()<=30,"Expiring Soon","Valid")))
F13: =IF(E13="","",EDATE(E13,24)) | G13: =IF(F13="","",IF(F13<TODAY(),"Expired",IF(F13-TODAY()<=30,"Expiring Soon","Valid")))
F14: =IF(E14="","",EDATE(E14,24)) | G14: =IF(F14="","",IF(F14<TODAY(),"Expired",IF(F14-TODAY()<=30,"Expiring Soon","Valid")))
... F102: =IF(E102="","",EDATE(E102,24)) | G102: =IF(F102="","",IF(F102<TODAY(),"Expired",IF(F102-TODAY()<=30,"Expiring Soon","Valid")))

Sheet SCBU
A1: SCBU — N95 Fit Test Tracking
A2: Employee Name | B2: Employee ID | C2: Department Email | D2: N95 Mask Type | E2: Fit Test Date | F2: Expiration Date | G2: Validation Status
F3: =IF(E3="","",EDATE(E3,24)) | G3: =IF(F3="","",IF(F3<TODAY(),"Expired",IF(F3-TODAY()<=30,"Expiring Soon","Valid")))
F4: =IF(E4="","",EDATE(E4,24)) | G4: =IF(F4="","",IF(F4<TODAY(),"Expired",IF(F4-TODAY()<=30,"Expiring Soon","Valid")))
F5: =IF(E5="","",EDATE(E5,24)) | G5: =IF(F5="","",IF(F5<TODAY(),"Expired",IF(F5-TODAY()<=30,"Expiring Soon","Valid")))
F6: =IF(E6="","",EDATE(E6,24)) | G6: =IF(F6="","",IF(F6<TODAY(),"Expired",IF(F6-TODAY()<=30,"Expiring Soon","Valid")))
F7: =IF(E7="","",EDATE(E7,24)) | G7: =IF(F7="","",IF(F7<TODAY(),"Expired",IF(F7-TODAY()<=30,"Expiring Soon","Valid")))
F8: =IF(E8="","",EDATE(E8,24)) | G8: =IF(F8="","",IF(F8<TODAY(),"Expired",IF(F8-TODAY()<=30,"Expiring Soon","Valid")))
F9: =IF(E9="","",EDATE(E9,24)) | G9: =IF(F9="","",IF(F9<TODAY(),"Expired",IF(F9-TODAY()<=30,"Expiring Soon","Valid")))
F10: =IF(E10="","",EDATE(E10,24)) | G10: =IF(F10="","",IF(F10<TODAY(),"Expired",IF(F10-TODAY()<=30,"Expiring Soon","Valid")))
F11: =IF(E11="","",EDATE(E11,24)) | G11: =IF(F11="","",IF(F11<TODAY(),"Expired",IF(F11-TODAY()<=30,"Expiring Soon","Valid")))
F12: =IF(E12="","",EDATE(E12,24)) | G12: =IF(F12="","",IF(F12<TODAY(),"Expired",IF(F12-TODAY()<=30,"Expiring Soon","Valid")))
F13: =IF(E13="","",EDATE(E13,24)) | G13: =IF(F13="","",IF(F13<TODAY(),"Expired",IF(F13-TODAY()<=30,"Expiring Soon","Valid")))
F14: =IF(E14="","",EDATE(E14,24)) | G14: =IF(F14="","",IF(F14<TODAY(),"Expired",IF(F14-TODAY()<=30,"Expiring Soon","Valid")))
... F102: =IF(E102="","",EDATE(E102,24)) | G102: =IF(F102="","",IF(F102<TODAY(),"Expired",IF(F102-TODAY()<=30,"Expiring Soon","Valid")))

Sheet SICU
A1: SICU — N95 Fit Test Tracking
A2: Employee Name | B2: Employee ID | C2: Department Email | D2: N95 Mask Type | E2: Fit Test Date | F2: Expiration Date | G2: Validation Status
F3: =IF(E3="","",EDATE(E3,24)) | G3: =IF(F3="","",IF(F3<TODAY(),"Expired",IF(F3-TODAY()<=30,"Expiring Soon","Valid")))
F4: =IF(E4="","",EDATE(E4,24)) | G4: =IF(F4="","",IF(F4<TODAY(),"Expired",IF(F4-TODAY()<=30,"Expiring Soon","Valid")))
F5: =IF(E5="","",EDATE(E5,24)) | G5: =IF(F5="","",IF(F5<TODAY(),"Expired",IF(F5-TODAY()<=30,"Expiring Soon","Valid")))
F6: =IF(E6="","",EDATE(E6,24)) | G6: =IF(F6="","",IF(F6<TODAY(),"Expired",IF(F6-TODAY()<=30,"Expiring Soon","Valid")))
F7: =IF(E7="","",EDATE(E7,24)) | G7: =IF(F7="","",IF(F7<TODAY(),"Expired",IF(F7-TODAY()<=30,"Expiring Soon","Valid")))
F8: =IF(E8="","",EDATE(E8,24)) | G8: =IF(F8="","",IF(F8<TODAY(),"Expired",IF(F8-TODAY()<=30,"Expiring Soon","Valid")))
F9: =IF(E9="","",EDATE(E9,24)) | G9: =IF(F9="","",IF(F9<TODAY(),"Expired",IF(F9-TODAY()<=30,"Expiring Soon","Valid")))
F10: =IF(E10="","",EDATE(E10,24)) | G10: =IF(F10="","",IF(F10<TODAY(),"Expired",IF(F10-TODAY()<=30,"Expiring Soon","Valid")))
F11: =IF(E11="","",EDATE(E11,24)) | G11: =IF(F11="","",IF(F11<TODAY(),"Expired",IF(F11-TODAY()<=30,"Expiring Soon","Valid")))
F12: =IF(E12="","",EDATE(E12,24)) | G12: =IF(F12="","",IF(F12<TODAY(),"Expired",IF(F12-TODAY()<=30,"Expiring Soon","Valid")))
F13: =IF(E13="","",EDATE(E13,24)) | G13: =IF(F13="","",IF(F13<TODAY(),"Expired",IF(F13-TODAY()<=30,"Expiring Soon","Valid")))
F14: =IF(E14="","",EDATE(E14,24)) | G14: =IF(F14="","",IF(F14<TODAY(),"Expired",IF(F14-TODAY()<=30,"Expiring Soon","Valid")))
... F102: =IF(E102="","",EDATE(E102,24)) | G102: =IF(F102="","",IF(F102<TODAY(),"Expired",IF(F102-TODAY()<=30,"Expiring Soon","Valid")))

Sheet PICU
A1: PICU — N95 Fit Test Tracking
A2: Employee Name | B2: Employee ID | C2: Department Email | D2: N95 Mask Type | E2: Fit Test Date | F2: Expiration Date | G2: Validation Status
F3: =IF(E3="","",EDATE(E3,24)) | G3: =IF(F3="","",IF(F3<TODAY(),"Expired",IF(F3-TODAY()<=30,"Expiring Soon","Valid")))
F4: =IF(E4="","",EDATE(E4,24)) | G4: =IF(F4="","",IF(F4<TODAY(),"Expired",IF(F4-TODAY()<=30,"Expiring Soon","Valid")))
F5: =IF(E5="","",EDATE(E5,24)) | G5: =IF(F5="","",IF(F5<TODAY(),"Expired",IF(F5-TODAY()<=30,"Expiring Soon","Valid")))
F6: =IF(E6="","",EDATE(E6,24)) | G6: =IF(F6="","",IF(F6<TODAY(),"Expired",IF(F6-TODAY()<=30,"Expiring Soon","Valid")))
F7: =IF(E7="","",EDATE(E7,24)) | G7: =IF(F7="","",IF(F7<TODAY(),"Expired",IF(F7-TODAY()<=30,"Expiring Soon","Valid")))
F8: =IF(E8="","",EDATE(E8,24)) | G8: =IF(F8="","",IF(F8<TODAY(),"Expired",IF(F8-TODAY()<=30,"Expiring Soon","Valid")))
F9: =IF(E9="","",EDATE(E9,24)) | G9: =IF(F9="","",IF(F9<TODAY(),"Expired",IF(F9-TODAY()<=30,"Expiring Soon","Valid")))
F10: =IF(E10="","",EDATE(E10,24)) | G10: =IF(F10="","",IF(F10<TODAY(),"Expired",IF(F10-TODAY()<=30,"Expiring Soon","Valid")))
F11: =IF(E11="","",EDATE(E11,24)) | G11: =IF(F11="","",IF(F11<TODAY(),"Expired",IF(F11-TODAY()<=30,"Expiring Soon","Valid")))
F12: =IF(E12="","",EDATE(E12,24)) | G12: =IF(F12="","",IF(F12<TODAY(),"Expired",IF(F12-TODAY()<=30,"Expiring Soon","Valid")))
F13: =IF(E13="","",EDATE(E13,24)) | G13: =IF(F13="","",IF(F13<TODAY(),"Expired",IF(F13-TODAY()<=30,"Expiring Soon","Valid")))
F14: =IF(E14="","",EDATE(E14,24)) | G14: =IF(F14="","",IF(F14<TODAY(),"Expired",IF(F14-TODAY()<=30,"Expiring Soon","Valid")))
... F102: =IF(E102="","",EDATE(E102,24)) | G102: =IF(F102="","",IF(F102<TODAY(),"Expired",IF(F102-TODAY()<=30,"Expiring Soon","Valid")))

Sheet NICU
A1: NICU — N95 Fit Test Tracking
A2: Employee Name | B2: Employee ID | C2: Department Email | D2: N95 Mask Type | E2: Fit Test Date | F2: Expiration Date | G2: Validation Status
F3: =IF(E3="","",EDATE(E3,24)) | G3: =IF(F3="","",IF(F3<TODAY(),"Expired",IF(F3-TODAY()<=30,"Expiring Soon","Valid")))
F4: =IF(E4="","",EDATE(E4,24)) | G4: =IF(F4="","",IF(F4<TODAY(),"Expired",IF(F4-TODAY()<=30,"Expiring Soon","Valid")))
F5: =IF(E5="","",EDATE(E5,24)) | G5: =IF(F5="","",IF(F5<TODAY(),"Expired",IF(F5-TODAY()<=30,"Expiring Soon","Valid")))
F6: =IF(E6="","",EDATE(E6,24)) | G6: =IF(F6="","",IF(F6<TODAY(),"Expired",IF(F6-TODAY()<=30,"Expiring Soon","Valid")))
F7: =IF(E7="","",EDATE(E7,24)) | G7: =IF(F7="","",IF(F7<TODAY(),"Expired",IF(F7-TODAY()<=30,"Expiring Soon","Valid")))
F8: =IF(E8="","",EDATE(E8,24)) | G8: =IF(F8="","",IF(F8<TODAY(),"Expired",IF(F8-TODAY()<=30,"Expiring Soon","Valid")))
F9: =IF(E9="","",EDATE(E9,24)) | G9: =IF(F9="","",IF(F9<TODAY(),"Expired",IF(F9-TODAY()<=30,"Expiring Soon","Valid")))
F10: =IF(E10="","",EDATE(E10,24)) | G10: =IF(F10="","",IF(F10<TODAY(),"Expired",IF(F10-TODAY()<=30,"Expiring Soon","Valid")))
F11: =IF(E11="","",EDATE(E11,24)) | G11: =IF(F11="","",IF(F11<TODAY(),"Expired",IF(F11-TODAY()<=30,"Expiring Soon","Valid")))
F12: =IF(E12="","",EDATE(E12,24)) | G12: =IF(F12="","",IF(F12<TODAY(),"Expired",IF(F12-TODAY()<=30,"Expiring Soon","Valid")))
F13: =IF(E13="","",EDATE(E13,24)) | G13: =IF(F13="","",IF(F13<TODAY(),"Expired",IF(F13-TODAY()<=30,"Expiring Soon","Valid")))
F14: =IF(E14="","",EDATE(E14,24)) | G14: =IF(F14="","",IF(F14<TODAY(),"Expired",IF(F14-TODAY()<=30,"Expiring Soon","Valid")))
... F102: =IF(E102="","",EDATE(E102,24)) | G102: =IF(F102="","",IF(F102<TODAY(),"Expired",IF(F102-TODAY()<=30,"Expiring Soon","Valid")))

Sheet L&D
A1: L&D — N95 Fit Test Tracking
A2: Employee Name | B2: Employee ID | C2: Department Email | D2: N95 Mask Type | E2: Fit Test Date | F2: Expiration Date | G2: Validation Status
F3: =IF(E3="","",EDATE(E3,24)) | G3: =IF(F3="","",IF(F3<TODAY(),"Expired",IF(F3-TODAY()<=30,"Expiring Soon","Valid")))
F4: =IF(E4="","",EDATE(E4,24)) | G4: =IF(F4="","",IF(F4<TODAY(),"Expired",IF(F4-TODAY()<=30,"Expiring Soon","Valid")))
F5: =IF(E5="","",EDATE(E5,24)) | G5: =IF(F5="","",IF(F5<TODAY(),"Expired",IF(F5-TODAY()<=30,"Expiring Soon","Valid")))
F6: =IF(E6="","",EDATE(E6,24)) | G6: =IF(F6="","",IF(F6<TODAY(),"Expired",IF(F6-TODAY()<=30,"Expiring Soon","Valid")))
F7: =IF(E7="","",EDATE(E7,24)) | G7: =IF(F7="","",IF(F7<TODAY(),"Expired",IF(F7-TODAY()<=30,"Expiring Soon","Valid")))
F8: =IF(E8="","",EDATE(E8,24)) | G8: =IF(F8="","",IF(F8<TODAY(),"Expired",IF(F8-TODAY()<=30,"Expiring Soon","Valid")))
F9: =IF(E9="","",EDATE(E9,24)) | G9: =IF(F9="","",IF(F9<TODAY(),"Expired",IF(F9-TODAY()<=30,"Expiring Soon","Valid")))
F10: =IF(E10="","",EDATE(E10,24)) | G10: =IF(F10="","",IF(F10<TODAY(),"Expired",IF(F10-TODAY()<=30,"Expiring Soon","Valid")))
F11: =IF(E11="","",EDATE(E11,24)) | G11: =IF(F11="","",IF(F11<TODAY(),"Expired",IF(F11-TODAY()<=30,"Expiring Soon","Valid")))
F12: =IF(E12="","",EDATE(E12,24)) | G12: =IF(F12="","",IF(F12<TODAY(),"Expired",IF(F12-TODAY()<=30,"Expiring Soon","Valid")))
F13: =IF(E13="","",EDATE(E13,24)) | G13: =IF(F13="","",IF(F13<TODAY(),"Expired",IF(F13-TODAY()<=30,"Expiring Soon","Valid")))
F14: =IF(E14="","",EDATE(E14,24)) | G14: =IF(F14="","",IF(F14<TODAY(),"Expired",IF(F14-TODAY()<=30,"Expiring Soon","Valid")))
... F102: =IF(E102="","",EDATE(E102,24)) | G102: =IF(F102="","",IF(F102<TODAY(),"Expired",IF(F102-TODAY()<=30,"Expiring Soon","Valid")))

Sheet OR
A1: OR — N95 Fit Test Tracking
A2: Employee Name | B2: Employee ID | C2: Department Email | D2: N95 Mask Type | E2: Fit Test Date | F2: Expiration Date | G2: Validation Status
F3: =IF(E3="","",EDATE(E3,24)) | G3: =IF(F3="","",IF(F3<TODAY(),"Expired",IF(F3-TODAY()<=30,"Expiring Soon","Valid")))
F4: =IF(E4="","",EDATE(E4,24)) | G4: =IF(F4="","",IF(F4<TODAY(),"Expired",IF(F4-TODAY()<=30,"Expiring Soon","Valid")))
F5: =IF(E5="","",EDATE(E5,24)) | G5: =IF(F5="","",IF(F5<TODAY(),"Expired",IF(F5-TODAY()<=30,"Expiring Soon","Valid")))
F6: =IF(E6="","",EDATE(E6,24)) | G6: =IF(F6="","",IF(F6<TODAY(),"Expired",IF(F6-TODAY()<=30,"Expiring Soon","Valid")))
F7: =IF(E7="","",EDATE(E7,24)) | G7: =IF(F7="","",IF(F7<TODAY(),"Expired",IF(F7-TODAY()<=30,"Expiring Soon","Valid")))
F8: =IF(E8="","",EDATE(E8,24)) | G8: =IF(F8="","",IF(F8<TODAY(),"Expired",IF(F8-TODAY()<=30,"Expiring Soon","Valid")))
F9: =IF(E9="","",EDATE(E9,24)) | G9: =IF(F9="","",IF(F9<TODAY(),"Expired",IF(F9-TODAY()<=30,"Expiring Soon","Valid")))
F10: =IF(E10="","",EDATE(E10,24)) | G10: =IF(F10="","",IF(F10<TODAY(),"Expired",IF(F10-TODAY()<=30,"Expiring Soon","Valid")))
F11: =IF(E11="","",EDATE(E11,24)) | G11: =IF(F11="","",IF(F11<TODAY(),"Expired",IF(F11-TODAY()<=30,"Expiring Soon","Valid")))
F12: =IF(E12="","",EDATE(E12,24)) | G12: =IF(F12="","",IF(F12<TODAY(),"Expired",IF(F12-TODAY()<=30,"Expiring Soon","Valid")))
F13: =IF(E13="","",EDATE(E13,24)) | G13: =IF(F13="","",IF(F13<TODAY(),"Expired",IF(F13-TODAY()<=30,"Expiring Soon","Valid")))
F14: =IF(E14="","",EDATE(E14,24)) | G14: =IF(F14="","",IF(F14<TODAY(),"Expired",IF(F14-TODAY()<=30,"Expiring Soon","Valid")))
... F102: =IF(E102="","",EDATE(E102,24)) | G102: =IF(F102="","",IF(F102<TODAY(),"Expired",IF(F102-TODAY()<=30,"Expiring Soon","Valid")))

Sheet Specialty Clinic
A1: Specialty Clinic — N95 Fit Test Tracking
A2: Employee Name | B2: Employee ID | C2: Department Email | D2: N95 Mask Type | E2: Fit Test Date | F2: Expiration Date | G2: Validation Status
F3: =IF(E3="","",EDATE(E3,24)) | G3: =IF(F3="","",IF(F3<TODAY(),"Expired",IF(F3-TODAY()<=30,"Expiring Soon","Valid")))
F4: =IF(E4="","",EDATE(E4,24)) | G4: =IF(F4="","",IF(F4<TODAY(),"Expired",IF(F4-TODAY()<=30,"Expiring Soon","Valid")))
F5: =IF(E5="","",EDATE(E5,24)) | G5: =IF(F5="","",IF(F5<TODAY(),"Expired",IF(F5-TODAY()<=30,"Expiring Soon","Valid")))
F6: =IF(E6="","",EDATE(E6,24)) | G6: =IF(F6="","",IF(F6<TODAY(),"Expired",IF(F6-TODAY()<=30,"Expiring Soon","Valid")))
F7: =IF(E7="","",EDATE(E7,24)) | G7: =IF(F7="","",IF(F7<TODAY(),"Expired",IF(F7-TODAY()<=30,"Expiring Soon","Valid")))
F8: =IF(E8="","",EDATE(E8,24)) | G8: =IF(F8="","",IF(F8<TODAY(),"Expired",IF(F8-TODAY()<=30,"Expiring Soon","Valid")))
F9: =IF(E9="","",EDATE(E9,24)) | G9: =IF(F9="","",IF(F9<TODAY(),"Expired",IF(F9-TODAY()<=30,"Expiring Soon","Valid")))
F10: =IF(E10="","",EDATE(E10,24)) | G10: =IF(F10="","",IF(F10<TODAY(),"Expired",IF(F10-TODAY()<=30,"Expiring Soon","Valid")))
F11: =IF(E11="","",EDATE(E11,24)) | G11: =IF(F11="","",IF(F11<TODAY(),"Expired",IF(F11-TODAY()<=30,"Expiring Soon","Valid")))
F12: =IF(E12="","",EDATE(E12,24)) | G12: =IF(F12="","",IF(F12<TODAY(),"Expired",IF(F12-TODAY()<=30,"Expiring Soon","Valid")))
F13: =IF(E13="","",EDATE(E13,24)) | G13: =IF(F13="","",IF(F13<TODAY(),"Expired",IF(F13-TODAY()<=30,"Expiring Soon","Valid")))
F14: =IF(E14="","",EDATE(E14,24)) | G14: =IF(F14="","",IF(F14<TODAY(),"Expired",IF(F14-TODAY()<=30,"Expiring Soon","Valid")))
... F102: =IF(E102="","",EDATE(E102,24)) | G102: =IF(F102="","",IF(F102<TODAY(),"Expired",IF(F102-TODAY()<=30,"Expiring Soon","Valid")))

Sheet Dental
A1: Dental — N95 Fit Test Tracking
A2: Employee Name | B2: Employee ID | C2: Department Email | D2: N95 Mask Type | E2: Fit Test Date | F2: Expiration Date | G2: Validation Status
F3: =IF(E3="","",EDATE(E3,24)) | G3: =IF(F3="","",IF(F3<TODAY(),"Expired",IF(F3-TODAY()<=30,"Expiring Soon","Valid")))
F4: =IF(E4="","",EDATE(E4,24)) | G4: =IF(F4="","",IF(F4<TODAY(),"Expired",IF(F4-TODAY()<=30,"Expiring Soon","Valid")))
F5: =IF(E5="","",EDATE(E5,24)) | G5: =IF(F5="","",IF(F5<TODAY(),"Expired",IF(F5-TODAY()<=30,"Expiring Soon","Valid")))
F6: =IF(E6="","",EDATE(E6,24)) | G6: =IF(F6="","",IF(F6<TODAY(),"Expired",IF(F6-TODAY()<=30,"Expiring Soon","Valid")))
F7: =IF(E7="","",EDATE(E7,24)) | G7: =IF(F7="","",IF(F7<TODAY(),"Expired",IF(F7-TODAY()<=30,"Expiring Soon","Valid")))
F8: =IF(E8="","",EDATE(E8,24)) | G8: =IF(F8="","",IF(F8<TODAY(),"Expired",IF(F8-TODAY()<=30,"Expiring Soon","Valid")))
F9: =IF(E9="","",EDATE(E9,24)) | G9: =IF(F9="","",IF(F9<TODAY(),"Expired",IF(F9-TODAY()<=30,"Expiring Soon","Valid")))
F10: =IF(E10="","",EDATE(E10,24)) | G10: =IF(F10="","",IF(F10<TODAY(),"Expired",IF(F10-TODAY()<=30,"Expiring Soon","Valid")))
F11: =IF(E11="","",EDATE(E11,24)) | G11: =IF(F11="","",IF(F11<TODAY(),"Expired",IF(F11-TODAY()<=30,"Expiring Soon","Valid")))
F12: =IF(E12="","",EDATE(E12,24)) | G12: =IF(F12="","",IF(F12<TODAY(),"Expired",IF(F12-TODAY()<=30,"Expiring Soon","Valid")))
F13: =IF(E13="","",EDATE(E13,24)) | G13: =IF(F13="","",IF(F13<TODAY(),"Expired",IF(F13-TODAY()<=30,"Expiring Soon","Valid")))
F14: =IF(E14="","",EDATE(E14,24)) | G14: =IF(F14="","",IF(F14<TODAY(),"Expired",IF(F14-TODAY()<=30,"Expiring Soon","Valid")))
... F102: =IF(E102="","",EDATE(E102,24)) | G102: =IF(F102="","",IF(F102<TODAY(),"Expired",IF(F102-TODAY()<=30,"Expiring Soon","Valid")))

Sheet FMW
A1: FMW — N95 Fit Test Tracking
A2: Employee Name | B2: Employee ID | C2: Department Email | D2: N95 Mask Type | E2: Fit Test Date | F2: Expiration Date | G2: Validation Status
F3: =IF(E3="","",EDATE(E3,24)) | G3: =IF(F3="","",IF(F3<TODAY(),"Expired",IF(F3-TODAY()<=30,"Expiring Soon","Valid")))
F4: =IF(E4="","",EDATE(E4,24)) | G4: =IF(F4="","",IF(F4<TODAY(),"Expired",IF(F4-TODAY()<=30,"Expiring Soon","Valid")))
F5: =IF(E5="","",EDATE(E5,24)) | G5: =IF(F5="","",IF(F5<TODAY(),"Expired",IF(F5-TODAY()<=30,"Expiring Soon","Valid")))
F6: =IF(E6="","",EDATE(E6,24)) | G6: =IF(F6="","",IF(F6<TODAY(),"Expired",IF(F6-TODAY()<=30,"Expiring Soon","Valid")))
F7: =IF(E7="","",EDATE(E7,24)) | G7: =IF(F7="","",IF(F7<TODAY(),"Expired",IF(F7-TODAY()<=30,"Expiring Soon","Valid")))
F8: =IF(E8="","",EDATE(E8,24)) | G8: =IF(F8="","",IF(F8<TODAY(),"Expired",IF(F8-TODAY()<=30,"Expiring Soon","Valid")))
F9: =IF(E9="","",EDATE(E9,24)) | G9: =IF(F9="","",IF(F9<TODAY(),"Expired",IF(F9-TODAY()<=30,"Expiring Soon","Valid")))
F10: =IF(E10="","",EDATE(E10,24)) | G10: =IF(F10="","",IF(F10<TODAY(),"Expired",IF(F10-TODAY()<=30,"Expiring Soon","Valid")))
F11: =IF(E11="","",EDATE(E11,24)) | G11: =IF(F11="","",IF(F11<TODAY(),"Expired",IF(F11-TODAY()<=30,"Expiring Soon","Valid")))
F12: =IF(E12="","",EDATE(E12,24)) | G12: =IF(F12="","",IF(F12<TODAY(),"Expired",IF(F12-TODAY()<=30,"Expiring Soon","Valid")))
F13: =IF(E13="","",EDATE(E13,24)) | G13: =IF(F13="","",IF(F13<TODAY(),"Expired",IF(F13-TODAY()<=30,"Expiring Soon","Valid")))
F14: =IF(E14="","",EDATE(E14,24)) | G14: =IF(F14="","",IF(F14<TODAY(),"Expired",IF(F14-TODAY()<=30,"Expiring Soon","Valid")))
... F102: =IF(E102="","",EDATE(E102,24)) | G102: =IF(F102="","",IF(F102<TODAY(),"Expired",IF(F102-TODAY()<=30,"Expiring Soon","Valid")))

Sheet OB
A1: OB — N95 Fit Test Tracking
A2: Employee Name | B2: Employee ID | C2: Department Email | D2: N95 Mask Type | E2: Fit Test Date | F2: Expiration Date | G2: Validation Status
F3: =IF(E3="","",EDATE(E3,24)) | G3: =IF(F3="","",IF(F3<TODAY(),"Expired",IF(F3-TODAY()<=30,"Expiring Soon","Valid")))
F4: =IF(E4="","",EDATE(E4,24)) | G4: =IF(F4="","",IF(F4<TODAY(),"Expired",IF(F4-TODAY()<=30,"Expiring Soon","Valid")))
F5: =IF(E5="","",EDATE(E5,24)) | G5: =IF(F5="","",IF(F5<TODAY(),"Expired",IF(F5-TODAY()<=30,"Expiring Soon","Valid")))
F6: =IF(E6="","",EDATE(E6,24)) | G6: =IF(F6="","",IF(F6<TODAY(),"Expired",IF(F6-TODAY()<=30,"Expiring Soon","Valid")))
F7: =IF(E7="","",EDATE(E7,24)) | G7: =IF(F7="","",IF(F7<TODAY(),"Expired",IF(F7-TODAY()<=30,"Expiring Soon","Valid")))
F8: =IF(E8="","",EDATE(E8,24)) | G8: =IF(F8="","",IF(F8<TODAY(),"Expired",IF(F8-TODAY()<=30,"Expiring Soon","Valid")))
F9: =IF(E9="","",EDATE(E9,24)) | G9: =IF(F9="","",IF(F9<TODAY(),"Expired",IF(F9-TODAY()<=30,"Expiring Soon","Valid")))
F10: =IF(E10="","",EDATE(E10,24)) | G10: =IF(F10="","",IF(F10<TODAY(),"Expired",IF(F10-TODAY()<=30,"Expiring Soon","Valid")))
F11: =IF(E11="","",EDATE(E11,24)) | G11: =IF(F11="","",IF(F11<TODAY(),"Expired",IF(F11-TODAY()<=30,"Expiring Soon","Valid")))
F12: =IF(E12="","",EDATE(E12,24)) | G12: =IF(F12="","",IF(F12<TODAY(),"Expired",IF(F12-TODAY()<=30,"Expiring Soon","Valid")))
F13: =IF(E13="","",EDATE(E13,24)) | G13: =IF(F13="","",IF(F13<TODAY(),"Expired",IF(F13-TODAY()<=30,"Expiring Soon","Valid")))
F14: =IF(E14="","",EDATE(E14,24)) | G14: =IF(F14="","",IF(F14<TODAY(),"Expired",IF(F14-TODAY()<=30,"Expiring Soon","Valid")))
... F102: =IF(E102="","",EDATE(E102,24)) | G102: =IF(F102="","",IF(F102<TODAY(),"Expired",IF(F102-TODAY()<=30,"Expiring Soon","Valid")))

Sheet NBN
A1: NBN — N95 Fit Test Tracking
A2: Employee Name | B2: Employee ID | C2: Department Email | D2: N95 Mask Type | E2: Fit Test Date | F2: Expiration Date | G2: Validation Status
F3: =IF(E3="","",EDATE(E3,24)) | G3: =IF(F3="","",IF(F3<TODAY(),"Expired",IF(F3-TODAY()<=30,"Expiring Soon","Valid")))
F4: =IF(E4="","",EDATE(E4,24)) | G4: =IF(F4="","",IF(F4<TODAY(),"Expired",IF(F4-TODAY()<=30,"Expiring Soon","Valid")))
F5: =IF(E5="","",EDATE(E5,24)) | G5: =IF(F5="","",IF(F5<TODAY(),"Expired",IF(F5-TODAY()<=30,"Expiring Soon","Valid")))
F6: =IF(E6="","",EDATE(E6,24)) | G6: =IF(F6="","",IF(F6<TODAY(),"Expired",IF(F6-TODAY()<=30,"Expiring Soon","Valid")))
F7: =IF(E7="","",EDATE(E7,24)) | G7: =IF(F7="","",IF(F7<TODAY(),"Expired",IF(F7-TODAY()<=30,"Expiring Soon","Valid")))
F8: =IF(E8="","",EDATE(E8,24)) | G8: =IF(F8="","",IF(F8<TODAY(),"Expired",IF(F8-TODAY()<=30,"Expiring Soon","Valid")))
F9: =IF(E9="","",EDATE(E9,24)) | G9: =IF(F9="","",IF(F9<TODAY(),"Expired",IF(F9-TODAY()<=30,"Expiring Soon","Valid")))
F10: =IF(E10="","",EDATE(E10,24)) | G10: =IF(F10="","",IF(F10<TODAY(),"Expired",IF(F10-TODAY()<=30,"Expiring Soon","Valid")))
F11: =IF(E11="","",EDATE(E11,24)) | G11: =IF(F11="","",IF(F11<TODAY(),"Expired",IF(F11-TODAY()<=30,"Expiring Soon","Valid")))
F12: =IF(E12="","",EDATE(E12,24)) | G12: =IF(F12="","",IF(F12<TODAY(),"Expired",IF(F12-TODAY()<=30,"Expiring Soon","Valid")))
F13: =IF(E13="","",EDATE(E13,24)) | G13: =IF(F13="","",IF(F13<TODAY(),"Expired",IF(F13-TODAY()<=30,"Expiring Soon","Valid")))
F14: =IF(E14="","",EDATE(E14,24)) | G14: =IF(F14="","",IF(F14<TODAY(),"Expired",IF(F14-TODAY()<=30,"Expiring Soon","Valid")))
... F102: =IF(E102="","",EDATE(E102,24)) | G102: =IF(F102="","",IF(F102<TODAY(),"Expired",IF(F102-TODAY()<=30,"Expiring Soon","Valid")))

Sheet Hemodialysis
A1: Hemodialysis — N95 Fit Test Tracking
A2: Employee Name | B2: Employee ID | C2: Department Email | D2: N95 Mask Type | E2: Fit Test Date | F2: Expiration Date | G2: Validation Status
F3: =IF(E3="","",EDATE(E3,24)) | G3: =IF(F3="","",IF(F3<TODAY(),"Expired",IF(F3-TODAY()<=30,"Expiring Soon","Valid")))
F4: =IF(E4="","",EDATE(E4,24)) | G4: =IF(F4="","",IF(F4<TODAY(),"Expired",IF(F4-TODAY()<=30,"Expiring Soon","Valid")))
F5: =IF(E5="","",EDATE(E5,24)) | G5: =IF(F5="","",IF(F5<TODAY(),"Expired",IF(F5-TODAY()<=30,"Expiring Soon","Valid")))
F6: =IF(E6="","",EDATE(E6,24)) | G6: =IF(F6="","",IF(F6<TODAY(),"Expired",IF(F6-TODAY()<=30,"Expiring Soon","Valid")))
F7: =IF(E7="","",EDATE(E7,24)) | G7: =IF(F7="","",IF(F7<TODAY(),"Expired",IF(F7-TODAY()<=30,"Expiring Soon","Valid")))
F8: =IF(E8="","",EDATE(E8,24)) | G8: =IF(F8="","",IF(F8<TODAY(),"Expired",IF(F8-TODAY()<=30,"Expiring Soon","Valid")))
F9: =IF(E9="","",EDATE(E9,24)) | G9: =IF(F9="","",IF(F9<TODAY(),"Expired",IF(F9-TODAY()<=30,"Expiring Soon","Valid")))
F10: =IF(E10="","",EDATE(E10,24)) | G10: =IF(F10="","",IF(F10<TODAY(),"Expired",IF(F10-TODAY()<=30,"Expiring Soon","Valid")))
F11: =IF(E11="","",EDATE(E11,24)) | G11: =IF(F11="","",IF(F11<TODAY(),"Expired",IF(F11-TODAY()<=30,"Expiring Soon","Valid")))
F12: =IF(E12="","",EDATE(E12,24)) | G12: =IF(F12="","",IF(F12<TODAY(),"Expired",IF(F12-TODAY()<=30,"Expiring Soon","Valid")))
F13: =IF(E13="","",EDATE(E13,24)) | G13: =IF(F13="","",IF(F13<TODAY(),"Expired",IF(F13-TODAY()<=30,"Expiring Soon","Valid")))
F14: =IF(E14="","",EDATE(E14,24)) | G14: =IF(F14="","",IF(F14<TODAY(),"Expired",IF(F14-TODAY()<=30,"Expiring Soon","Valid")))
... F102: =IF(E102="","",EDATE(E102,24)) | G102: =IF(F102="","",IF(F102<TODAY(),"Expired",IF(F102-TODAY()<=30,"Expiring Soon","Valid")))

Sheet Cardiac Center
A1: Cardiac Center — N95 Fit Test Tracking
A2: Employee Name | B2: Employee ID | C2: Department Email | D2: N95 Mask Type | E2: Fit Test Date | F2: Expiration Date | G2: Validation Status
F3: =IF(E3="","",EDATE(E3,24)) | G3: =IF(F3="","",IF(F3<TODAY(),"Expired",IF(F3-TODAY()<=30,"Expiring Soon","Valid")))
F4: =IF(E4="","",EDATE(E4,24)) | G4: =IF(F4="","",IF(F4<TODAY(),"Expired",IF(F4-TODAY()<=30,"Expiring Soon","Valid")))
F5: =IF(E5="","",EDATE(E5,24)) | G5: =IF(F5="","",IF(F5<TODAY(),"Expired",IF(F5-TODAY()<=30,"Expiring Soon","Valid")))
F6: =IF(E6="","",EDATE(E6,24)) | G6: =IF(F6="","",IF(F6<TODAY(),"Expired",IF(F6-TODAY()<=30,"Expiring Soon","Valid")))
F7: =IF(E7="","",EDATE(E7,24)) | G7: =IF(F7="","",IF(F7<TODAY(),"Expired",IF(F7-TODAY()<=30,"Expiring Soon","Valid")))
F8: =IF(E8="","",EDATE(E8,24)) | G8: =IF(F8="","",IF(F8<TODAY(),"Expired",IF(F8-TODAY()<=30,"Expiring Soon","Valid")))
F9: =IF(E9="","",EDATE(E9,24)) | G9: =IF(F9="","",IF(F9<TODAY(),"Expired",IF(F9-TODAY()<=30,"Expiring Soon","Valid")))
F10: =IF(E10="","",EDATE(E10,24)) | G10: =IF(F10="","",IF(F10<TODAY(),"Expired",IF(F10-TODAY()<=30,"Expiring Soon","Valid")))
F11: =IF(E11="","",EDATE(E11,24)) | G11: =IF(F11="","",IF(F11<TODAY(),"Expired",IF(F11-TODAY()<=30,"Expiring Soon","Valid")))
F12: =IF(E12="","",EDATE(E12,24)) | G12: =IF(F12="","",IF(F12<TODAY(),"Expired",IF(F12-TODAY()<=30,"Expiring Soon","Valid")))
F13: =IF(E13="","",EDATE(E13,24)) | G13: =IF(F13="","",IF(F13<TODAY(),"Expired",IF(F13-TODAY()<=30,"Expiring Soon","Valid")))
F14: =IF(E14="","",EDATE(E14,24)) | G14: =IF(F14="","",IF(F14<TODAY(),"Expired",IF(F14-TODAY()<=30,"Expiring Soon","Valid")))
... F102: =IF(E102="","",EDATE(E102,24)) | G102: =IF(F102="","",IF(F102<TODAY(),"Expired",IF(F102-TODAY()<=30,"Expiring Soon","Valid")))

Sheet PW
A1: PW — N95 Fit Test Tracking
A2: Employee Name | B2: Employee ID | C2: Department Email | D2: N95 Mask Type | E2: Fit Test Date | F2: Expiration Date | G2: Validation Status
F3: =IF(E3="","",EDATE(E3,24)) | G3: =IF(F3="","",IF(F3<TODAY(),"Expired",IF(F3-TODAY()<=30,"Expiring Soon","Valid")))
F4: =IF(E4="","",EDATE(E4,24)) | G4: =IF(F4="","",IF(F4<TODAY(),"Expired",IF(F4-TODAY()<=30,"Expiring Soon","Valid")))
F5: =IF(E5="","",EDATE(E5,24)) | G5: =IF(F5="","",IF(F5<TODAY(),"Expired",IF(F5-TODAY()<=30,"Expiring Soon","Valid")))
F6: =IF(E6="","",EDATE(E6,24)) | G6: =IF(F6="","",IF(F6<TODAY(),"Expired",IF(F6-TODAY()<=30,"Expiring Soon","Valid")))
F7: =IF(E7="","",EDATE(E7,24)) | G7: =IF(F7="","",IF(F7<TODAY(),"Expired",IF(F7-TODAY()<=30,"Expiring Soon","Valid")))
F8: =IF(E8="","",EDATE(E8,24)) | G8: =IF(F8="","",IF(F8<TODAY(),"Expired",IF(F8-TODAY()<=30,"Expiring Soon","Valid")))
F9: =IF(E9="","",EDATE(E9,24)) | G9: =IF(F9="","",IF(F9<TODAY(),"Expired",IF(F9-TODAY()<=30,"Expiring Soon","Valid")))
F10: =IF(E10="","",EDATE(E10,24)) | G10: =IF(F10="","",IF(F10<TODAY(),"Expired",IF(F10-TODAY()<=30,"Expiring Soon","Valid")))
F11: =IF(E11="","",EDATE(E11,24)) | G11: =IF(F11="","",IF(F11<TODAY(),"Expired",IF(F11-TODAY()<=30,"Expiring Soon","Valid")))
F12: =IF(E12="","",EDATE(E12,24)) | G12: =IF(F12="","",IF(F12<TODAY(),"Expired",IF(F12-TODAY()<=30,"Expiring Soon","Valid")))
F13: =IF(E13="","",EDATE(E13,24)) | G13: =IF(F13="","",IF(F13<TODAY(),"Expired",IF(F13-TODAY()<=30,"Expiring Soon","Valid")))
F14: =IF(E14="","",EDATE(E14,24)) | G14: =IF(F14="","",IF(F14<TODAY(),"Expired",IF(F14-TODAY()<=30,"Expiring Soon","Valid")))
... F102: =IF(E102="","",EDATE(E102,24)) | G102: =IF(F102="","",IF(F102<TODAY(),"Expired",IF(F102-TODAY()<=30,"Expiring Soon","Valid")))

Sheet FSW
A1: FSW — N95 Fit Test Tracking
A2: Employee Name | B2: Employee ID | C2: Department Email | D2: N95 Mask Type | E2: Fit Test Date | F2: Expiration Date | G2: Validation Status
F3: =IF(E3="","",EDATE(E3,24)) | G3: =IF(F3="","",IF(F3<TODAY(),"Expired",IF(F3-TODAY()<=30,"Expiring Soon","Valid")))
F4: =IF(E4="","",EDATE(E4,24)) | G4: =IF(F4="","",IF(F4<TODAY(),"Expired",IF(F4-TODAY()<=30,"Expiring Soon","Valid")))
F5: =IF(E5="","",EDATE(E5,24)) | G5: =IF(F5="","",IF(F5<TODAY(),"Expired",IF(F5-TODAY()<=30,"Expiring Soon","Valid")))
F6: =IF(E6="","",EDATE(E6,24)) | G6: =IF(F6="","",IF(F6<TODAY(),"Expired",IF(F6-TODAY()<=30,"Expiring Soon","Valid")))
F7: =IF(E7="","",EDATE(E7,24)) | G7: =IF(F7="","",IF(F7<TODAY(),"Expired",IF(F7-TODAY()<=30,"Expiring Soon","Valid")))
F8: =IF(E8="","",EDATE(E8,24)) | G8: =IF(F8="","",IF(F8<TODAY(),"Expired",IF(F8-TODAY()<=30,"Expiring Soon","Valid")))
F9: =IF(E9="","",EDATE(E9,24)) | G9: =IF(F9="","",IF(F9<TODAY(),"Expired",IF(F9-TODAY()<=30,"Expiring Soon","Valid")))
F10: =IF(E10="","",EDATE(E10,24)) | G10: =IF(F10="","",IF(F10<TODAY(),"Expired",IF(F10-TODAY()<=30,"Expiring Soon","Valid")))
F11: =IF(E11="","",EDATE(E11,24)) | G11: =IF(F11="","",IF(F11<TODAY(),"Expired",IF(F11-TODAY()<=30,"Expiring Soon","Valid")))
F12: =IF(E12="","",EDATE(E12,24)) | G12: =IF(F12="","",IF(F12<TODAY(),"Expired",IF(F12-TODAY()<=30,"Expiring Soon","Valid")))
F13: =IF(E13="","",EDATE(E13,24)) | G13: =IF(F13="","",IF(F13<TODAY(),"Expired",IF(F13-TODAY()<=30,"Expiring Soon","Valid")))
F14: =IF(E14="","",EDATE(E14,24)) | G14: =IF(F14="","",IF(F14<TODAY(),"Expired",IF(F14-TODAY()<=30,"Expiring Soon","Valid")))
... F102: =IF(E102="","",EDATE(E102,24)) | G102: =IF(F102="","",IF(F102<TODAY(),"Expired",IF(F102-TODAY()<=30,"Expiring Soon","Valid")))

Sheet Endoscopy
A1: Endoscopy — N95 Fit Test Tracking
A2: Employee Name | B2: Employee ID | C2: Department Email | D2: N95 Mask Type | E2: Fit Test Date | F2: Expiration Date | G2: Validation Status
F3: =IF(E3="","",EDATE(E3,24)) | G3: =IF(F3="","",IF(F3<TODAY(),"Expired",IF(F3-TODAY()<=30,"Expiring Soon","Valid")))
F4: =IF(E4="","",EDATE(E4,24)) | G4: =IF(F4="","",IF(F4<TODAY(),"Expired",IF(F4-TODAY()<=30,"Expiring Soon","Valid")))
F5: =IF(E5="","",EDATE(E5,24)) | G5: =IF(F5="","",IF(F5<TODAY(),"Expired",IF(F5-TODAY()<=30,"Expiring Soon","Valid")))
F6: =IF(E6="","",EDATE(E6,24)) | G6: =IF(F6="","",IF(F6<TODAY(),"Expired",IF(F6-TODAY()<=30,"Expiring Soon","Valid")))
F7: =IF(E7="","",EDATE(E7,24)) | G7: =IF(F7="","",IF(F7<TODAY(),"Expired",IF(F7-TODAY()<=30,"Expiring Soon","Valid")))
F8: =IF(E8="","",EDATE(E8,24)) | G8: =IF(F8="","",IF(F8<TODAY(),"Expired",IF(F8-TODAY()<=30,"Expiring Soon","Valid")))
F9: =IF(E9="","",EDATE(E9,24)) | G9: =IF(F9="","",IF(F9<TODAY(),"Expired",IF(F9-TODAY()<=30,"Expiring Soon","Valid")))
F10: =IF(E10="","",EDATE(E10,24)) | G10: =IF(F10="","",IF(F10<TODAY(),"Expired",IF(F10-TODAY()<=30,"Expiring Soon","Valid")))
F11: =IF(E11="","",EDATE(E11,24)) | G11: =IF(F11="","",IF(F11<TODAY(),"Expired",IF(F11-TODAY()<=30,"Expiring Soon","Valid")))
F12: =IF(E12="","",EDATE(E12,24)) | G12: =IF(F12="","",IF(F12<TODAY(),"Expired",IF(F12-TODAY()<=30,"Expiring Soon","Valid")))
F13: =IF(E13="","",EDATE(E13,24)) | G13: =IF(F13="","",IF(F13<TODAY(),"Expired",IF(F13-TODAY()<=30,"Expiring Soon","Valid")))
F14: =IF(E14="","",EDATE(E14,24)) | G14: =IF(F14="","",IF(F14<TODAY(),"Expired",IF(F14-TODAY()<=30,"Expiring Soon","Valid")))
... F102: =IF(E102="","",EDATE(E102,24)) | G102: =IF(F102="","",IF(F102<TODAY(),"Expired",IF(F102-TODAY()<=30,"Expiring Soon","Valid")))

Sheet HK
A1: HK — N95 Fit Test Tracking
A2: Employee Name | B2: Employee ID | C2: Department Email | D2: N95 Mask Type | E2: Fit Test Date | F2: Expiration Date | G2: Validation Status
F3: =IF(E3="","",EDATE(E3,24)) | G3: =IF(F3="","",IF(F3<TODAY(),"Expired",IF(F3-TODAY()<=30,"Expiring Soon","Valid")))
F4: =IF(E4="","",EDATE(E4,24)) | G4: =IF(F4="","",IF(F4<TODAY(),"Expired",IF(F4-TODAY()<=30,"Expiring Soon","Valid")))
F5: =IF(E5="","",EDATE(E5,24)) | G5: =IF(F5="","",IF(F5<TODAY(),"Expired",IF(F5-TODAY()<=30,"Expiring Soon","Valid")))
F6: =IF(E6="","",EDATE(E6,24)) | G6: =IF(F6="","",IF(F6<TODAY(),"Expired",IF(F6-TODAY()<=30,"Expiring Soon","Valid")))
F7: =IF(E7="","",EDATE(E7,24)) | G7: =IF(F7="","",IF(F7<TODAY(),"Expired",IF(F7-TODAY()<=30,"Expiring Soon","Valid")))
F8: =IF(E8="","",EDATE(E8,24)) | G8: =IF(F8="","",IF(F8<TODAY(),"Expired",IF(F8-TODAY()<=30,"Expiring Soon","Valid")))
F9: =IF(E9="","",EDATE(E9,24)) | G9: =IF(F9="","",IF(F9<TODAY(),"Expired",IF(F9-TODAY()<=30,"Expiring Soon","Valid")))
F10: =IF(E10="","",EDATE(E10,24)) | G10: =IF(F10="","",IF(F10<TODAY(),"Expired",IF(F10-TODAY()<=30,"Expiring Soon","Valid")))
F11: =IF(E11="","",EDATE(E11,24)) | G11: =IF(F11="","",IF(F11<TODAY(),"Expired",IF(F11-TODAY()<=30,"Expiring Soon","Valid")))
F12: =IF(E12="","",EDATE(E12,24)) | G12: =IF(F12="","",IF(F12<TODAY(),"Expired",IF(F12-TODAY()<=30,"Expiring Soon","Valid")))
F13: =IF(E13="","",EDATE(E13,24)) | G13: =IF(F13="","",IF(F13<TODAY(),"Expired",IF(F13-TODAY()<=30,"Expiring Soon","Valid")))
F14: =IF(E14="","",EDATE(E14,24)) | G14: =IF(F14="","",IF(F14<TODAY(),"Expired",IF(F14-TODAY()<=30,"Expiring Soon","Valid")))
... F102: =IF(E102="","",EDATE(E102,24)) | G102: =IF(F102="","",IF(F102<TODAY(),"Expired",IF(F102-TODAY()<=30,"Expiring Soon","Valid")))

Sheet FMC
A1: FMC — N95 Fit Test Tracking
A2: Employee Name | B2: Employee ID | C2: Department Email | D2: N95 Mask Type | E2: Fit Test Date | F2: Expiration Date | G2: Validation Status
F3: =IF(E3="","",EDATE(E3,24)) | G3: =IF(F3="","",IF(F3<TODAY(),"Expired",IF(F3-TODAY()<=30,"Expiring Soon","Valid")))
F4: =IF(E4="","",EDATE(E4,24)) | G4: =IF(F4="","",IF(F4<TODAY(),"Expired",IF(F4-TODAY()<=30,"Expiring Soon","Valid")))
F5: =IF(E5="","",EDATE(E5,24)) | G5: =IF(F5="","",IF(F5<TODAY(),"Expired",IF(F5-TODAY()<=30,"Expiring Soon","Valid")))
F6: =IF(E6="","",EDATE(E6,24)) | G6: =IF(F6="","",IF(F6<TODAY(),"Expired",IF(F6-TODAY()<=30,"Expiring Soon","Valid")))
F7: =IF(E7="","",EDATE(E7,24)) | G7: =IF(F7="","",IF(F7<TODAY(),"Expired",IF(F7-TODAY()<=30,"Expiring Soon","Valid")))
F8: =IF(E8="","",EDATE(E8,24)) | G8: =IF(F8="","",IF(F8<TODAY(),"Expired",IF(F8-TODAY()<=30,"Expiring Soon","Valid")))
F9: =IF(E9="","",EDATE(E9,24)) | G9: =IF(F9="","",IF(F9<TODAY(),"Expired",IF(F9-TODAY()<=30,"Expiring Soon","Valid")))
F10: =IF(E10="","",EDATE(E10,24)) | G10: =IF(F10="","",IF(F10<TODAY(),"Expired",IF(F10-TODAY()<=30,"Expiring Soon","Valid")))
F11: =IF(E11="","",EDATE(E11,24)) | G11: =IF(F11="","",IF(F11<TODAY(),"Expired",IF(F11-TODAY()<=30,"Expiring Soon","Valid")))
F12: =IF(E12="","",EDATE(E12,24)) | G12: =IF(F12="","",IF(F12<TODAY(),"Expired",IF(F12-TODAY()<=30,"Expiring Soon","Valid")))
F13: =IF(E13="","",EDATE(E13,24)) | G13: =IF(F13="","",IF(F13<TODAY(),"Expired",IF(F13-TODAY()<=30,"Expiring Soon","Valid")))
F14: =IF(E14="","",EDATE(E14,24)) | G14: =IF(F14="","",IF(F14<TODAY(),"Expired",IF(F14-TODAY()<=30,"Expiring Soon","Valid")))
... F102: =IF(E102="","",EDATE(E102,24)) | G102: =IF(F102="","",IF(F102<TODAY(),"Expired",IF(F102-TODAY()<=30,"Expiring Soon","Valid")))

Sheet MMW
A1: MMW — N95 Fit Test Tracking
A2: Employee Name | B2: Employee ID | C2: Department Email | D2: N95 Mask Type | E2: Fit Test Date | F2: Expiration Date | G2: Validation Status
F3: =IF(E3="","",EDATE(E3,24)) | G3: =IF(F3="","",IF(F3<TODAY(),"Expired",IF(F3-TODAY()<=30,"Expiring Soon","Valid")))
F4: =IF(E4="","",EDATE(E4,24)) | G4: =IF(F4="","",IF(F4<TODAY(),"Expired",IF(F4-TODAY()<=30,"Expiring Soon","Valid")))
F5: =IF(E5="","",EDATE(E5,24)) | G5: =IF(F5="","",IF(F5<TODAY(),"Expired",IF(F5-TODAY()<=30,"Expiring Soon","Valid")))
F6: =IF(E6="","",EDATE(E6,24)) | G6: =IF(F6="","",IF(F6<TODAY(),"Expired",IF(F6-TODAY()<=30,"Expiring Soon","Valid")))
F7: =IF(E7="","",EDATE(E7,24)) | G7: =IF(F7="","",IF(F7<TODAY(),"Expired",IF(F7-TODAY()<=30,"Expiring Soon","Valid")))
F8: =IF(E8="","",EDATE(E8,24)) | G8: =IF(F8="","",IF(F8<TODAY(),"Expired",IF(F8-TODAY()<=30,"Expiring Soon","Valid")))
F9: =IF(E9="","",EDATE(E9,24)) | G9: =IF(F9="","",IF(F9<TODAY(),"Expired",IF(F9-TODAY()<=30,"Expiring Soon","Valid")))
F10: =IF(E10="","",EDATE(E10,24)) | G10: =IF(F10="","",IF(F10<TODAY(),"Expired",IF(F10-TODAY()<=30,"Expiring Soon","Valid")))
F11: =IF(E11="","",EDATE(E11,24)) | G11: =IF(F11="","",IF(F11<TODAY(),"Expired",IF(F11-TODAY()<=30,"Expiring Soon","Valid")))
F12: =IF(E12="","",EDATE(E12,24)) | G12: =IF(F12="","",IF(F12<TODAY(),"Expired",IF(F12-TODAY()<=30,"Expiring Soon","Valid")))
F13: =IF(E13="","",EDATE(E13,24)) | G13: =IF(F13="","",IF(F13<TODAY(),"Expired",IF(F13-TODAY()<=30,"Expiring Soon","Valid")))
F14: =IF(E14="","",EDATE(E14,24)) | G14: =IF(F14="","",IF(F14<TODAY(),"Expired",IF(F14-TODAY()<=30,"Expiring Soon","Valid")))
... F102: =IF(E102="","",EDATE(E102,24)) | G102: =IF(F102="","",IF(F102<TODAY(),"Expired",IF(F102-TODAY()<=30,"Expiring Soon","Valid")))

Sheet MSW
A1: MSW — N95 Fit Test Tracking
A2: Employee Name | B2: Employee ID | C2: Department Email | D2: N95 Mask Type | E2: Fit Test Date | F2: Expiration Date | G2: Validation Status
F3: =IF(E3="","",EDATE(E3,24)) | G3: =IF(F3="","",IF(F3<TODAY(),"Expired",IF(F3-TODAY()<=30,"Expiring Soon","Valid")))
F4: =IF(E4="","",EDATE(E4,24)) | G4: =IF(F4="","",IF(F4<TODAY(),"Expired",IF(F4-TODAY()<=30,"Expiring Soon","Valid")))
F5: =IF(E5="","",EDATE(E5,24)) | G5: =IF(F5="","",IF(F5<TODAY(),"Expired",IF(F5-TODAY()<=30,"Expiring Soon","Valid")))
F6: =IF(E6="","",EDATE(E6,24)) | G6: =IF(F6="","",IF(F6<TODAY(),"Expired",IF(F6-TODAY()<=30,"Expiring Soon","Valid")))
F7: =IF(E7="","",EDATE(E7,24)) | G7: =IF(F7="","",IF(F7<TODAY(),"Expired",IF(F7-TODAY()<=30,"Expiring Soon","Valid")))
F8: =IF(E8="","",EDATE(E8,24)) | G8: =IF(F8="","",IF(F8<TODAY(),"Expired",IF(F8-TODAY()<=30,"Expiring Soon","Valid")))
F9: =IF(E9="","",EDATE(E9,24)) | G9: =IF(F9="","",IF(F9<TODAY(),"Expired",IF(F9-TODAY()<=30,"Expiring Soon","Valid")))
F10: =IF(E10="","",EDATE(E10,24)) | G10: =IF(F10="","",IF(F10<TODAY(),"Expired",IF(F10-TODAY()<=30,"Expiring Soon","Valid")))
F11: =IF(E11="","",EDATE(E11,24)) | G11: =IF(F11="","",IF(F11<TODAY(),"Expired",IF(F11-TODAY()<=30,"Expiring Soon","Valid")))
F12: =IF(E12="","",EDATE(E12,24)) | G12: =IF(F12="","",IF(F12<TODAY(),"Expired",IF(F12-TODAY()<=30,"Expiring Soon","Valid")))
F13: =IF(E13="","",EDATE(E13,24)) | G13: =IF(F13="","",IF(F13<TODAY(),"Expired",IF(F13-TODAY()<=30,"Expiring Soon","Valid")))
F14: =IF(E14="","",EDATE(E14,24)) | G14: =IF(F14="","",IF(F14<TODAY(),"Expired",IF(F14-TODAY()<=30,"Expiring Soon","Valid")))
... F102: =IF(E102="","",EDATE(E102,24)) | G102: =IF(F102="","",IF(F102<TODAY(),"Expired",IF(F102-TODAY()<=30,"Expiring Soon","Valid")))

Sheet CW
A1: CW — N95 Fit Test Tracking
A2: Employee Name | B2: Employee ID | C2: Department Email | D2: N95 Mask Type | E2: Fit Test Date | F2: Expiration Date | G2: Validation Status
F3: =IF(E3="","",EDATE(E3,24)) | G3: =IF(F3="","",IF(F3<TODAY(),"Expired",IF(F3-TODAY()<=30,"Expiring Soon","Valid")))
F4: =IF(E4="","",EDATE(E4,24)) | G4: =IF(F4="","",IF(F4<TODAY(),"Expired",IF(F4-TODAY()<=30,"Expiring Soon","Valid")))
F5: =IF(E5="","",EDATE(E5,24)) | G5: =IF(F5="","",IF(F5<TODAY(),"Expired",IF(F5-TODAY()<=30,"Expiring Soon","Valid")))
F6: =IF(E6="","",EDATE(E6,24)) | G6: =IF(F6="","",IF(F6<TODAY(),"Expired",IF(F6-TODAY()<=30,"Expiring Soon","Valid")))
F7: =IF(E7="","",EDATE(E7,24)) | G7: =IF(F7="","",IF(F7<TODAY(),"Expired",IF(F7-TODAY()<=30,"Expiring Soon","Valid")))
F8: =IF(E8="","",EDATE(E8,24)) | G8: =IF(F8="","",IF(F8<TODAY(),"Expired",IF(F8-TODAY()<=30,"Expiring Soon","Valid")))
F9: =IF(E9="","",EDATE(E9,24)) | G9: =IF(F9="","",IF(F9<TODAY(),"Expired",IF(F9-TODAY()<=30,"Expiring Soon","Valid")))
F10: =IF(E10="","",EDATE(E10,24)) | G10: =IF(F10="","",IF(F10<TODAY(),"Expired",IF(F10-TODAY()<=30,"Expiring Soon","Valid")))
F11: =IF(E11="","",EDATE(E11,24)) | G11: =IF(F11="","",IF(F11<TODAY(),"Expired",IF(F11-TODAY()<=30,"Expiring Soon","Valid")))
F12: =IF(E12="","",EDATE(E12,24)) | G12: =IF(F12="","",IF(F12<TODAY(),"Expired",IF(F12-TODAY()<=30,"Expiring Soon","Valid")))
F13: =IF(E13="","",EDATE(E13,24)) | G13: =IF(F13="","",IF(F13<TODAY(),"Expired",IF(F13-TODAY()<=30,"Expiring Soon","Valid")))
F14: =IF(E14="","",EDATE(E14,24)) | G14: =IF(F14="","",IF(F14<TODAY(),"Expired",IF(F14-TODAY()<=30,"Expiring Soon","Valid")))
... F102: =IF(E102="","",EDATE(E102,24)) | G102: =IF(F102="","",IF(F102<TODAY(),"Expired",IF(F102-TODAY()<=30,"Expiring Soon","Valid")))

Sheet Radiology
A1: Radiology — N95 Fit Test Tracking
A2: Employee Name | B2: Employee ID | C2: Department Email | D2: N95 Mask Type | E2: Fit Test Date | F2: Expiration Date | G2: Validation Status
F3: =IF(E3="","",EDATE(E3,24)) | G3: =IF(F3="","",IF(F3<TODAY(),"Expired",IF(F3-TODAY()<=30,"Expiring Soon","Valid")))
F4: =IF(E4="","",EDATE(E4,24)) | G4: =IF(F4="","",IF(F4<TODAY(),"Expired",IF(F4-TODAY()<=30,"Expiring Soon","Valid")))
F5: =IF(E5="","",EDATE(E5,24)) | G5: =IF(F5="","",IF(F5<TODAY(),"Expired",IF(F5-TODAY()<=30,"Expiring Soon","Valid")))
F6: =IF(E6="","",EDATE(E6,24)) | G6: =IF(F6="","",IF(F6<TODAY(),"Expired",IF(F6-TODAY()<=30,"Expiring Soon","Valid")))
F7: =IF(E7="","",EDATE(E7,24)) | G7: =IF(F7="","",IF(F7<TODAY(),"Expired",IF(F7-TODAY()<=30,"Expiring Soon","Valid")))
F8: =IF(E8="","",EDATE(E8,24)) | G8: =IF(F8="","",IF(F8<TODAY(),"Expired",IF(F8-TODAY()<=30,"Expiring Soon","Valid")))
F9: =IF(E9="","",EDATE(E9,24)) | G9: =IF(F9="","",IF(F9<TODAY(),"Expired",IF(F9-TODAY()<=30,"Expiring Soon","Valid")))
F10: =IF(E10="","",EDATE(E10,24)) | G10: =IF(F10="","",IF(F10<TODAY(),"Expired",IF(F10-TODAY()<=30,"Expiring Soon","Valid")))
F11: =IF(E11="","",EDATE(E11,24)) | G11: =IF(F11="","",IF(F11<TODAY(),"Expired",IF(F11-TODAY()<=30,"Expiring Soon","Valid")))
F12: =IF(E12="","",EDATE(E12,24)) | G12: =IF(F12="","",IF(F12<TODAY(),"Expired",IF(F12-TODAY()<=30,"Expiring Soon","Valid")))
F13: =IF(E13="","",EDATE(E13,24)) | G13: =IF(F13="","",IF(F13<TODAY(),"Expired",IF(F13-TODAY()<=30,"Expiring Soon","Valid")))
F14: =IF(E14="","",EDATE(E14,24)) | G14: =IF(F14="","",IF(F14<TODAY(),"Expired",IF(F14-TODAY()<=30,"Expiring Soon","Valid")))
... F102: =IF(E102="","",EDATE(E102,24)) | G102: =IF(F102="","",IF(F102<TODAY(),"Expired",IF(F102-TODAY()<=30,"Expiring Soon","Valid")))

Sheet HHC
A1: HHC — N95 Fit Test Tracking
A2: Employee Name | B2: Employee ID | C2: Department Email | D2: N95 Mask Type | E2: Fit Test Date | F2: Expiration Date | G2: Validation Status
F3: =IF(E3="","",EDATE(E3,24)) | G3: =IF(F3="","",IF(F3<TODAY(),"Expired",IF(F3-TODAY()<=30,"Expiring Soon","Valid")))
F4: =IF(E4="","",EDATE(E4,24)) | G4: =IF(F4="","",IF(F4<TODAY(),"Expired",IF(F4-TODAY()<=30,"Expiring Soon","Valid")))
F5: =IF(E5="","",EDATE(E5,24)) | G5: =IF(F5="","",IF(F5<TODAY(),"Expired",IF(F5-TODAY()<=30,"Expiring Soon","Valid")))
F6: =IF(E6="","",EDATE(E6,24)) | G6: =IF(F6="","",IF(F6<TODAY(),"Expired",IF(F6-TODAY()<=30,"Expiring Soon","Valid")))
F7: =IF(E7="","",EDATE(E7,24)) | G7: =IF(F7="","",IF(F7<TODAY(),"Expired",IF(F7-TODAY()<=30,"Expiring Soon","Valid")))
F8: =IF(E8="","",EDATE(E8,24)) | G8: =IF(F8="","",IF(F8<TODAY(),"Expired",IF(F8-TODAY()<=30,"Expiring Soon","Valid")))
F9: =IF(E9="","",EDATE(E9,24)) | G9: =IF(F9="","",IF(F9<TODAY(),"Expired",IF(F9-TODAY()<=30,"Expiring Soon","Valid")))
F10: =IF(E10="","",EDATE(E10,24)) | G10: =IF(F10="","",IF(F10<TODAY(),"Expired",IF(F10-TODAY()<=30,"Expiring Soon","Valid")))
F11: =IF(E11="","",EDATE(E11,24)) | G11: =IF(F11="","",IF(F11<TODAY(),"Expired",IF(F11-TODAY()<=30,"Expiring Soon","Valid")))
F12: =IF(E12="","",EDATE(E12,24)) | G12: =IF(F12="","",IF(F12<TODAY(),"Expired",IF(F12-TODAY()<=30,"Expiring Soon","Valid")))
F13: =IF(E13="","",EDATE(E13,24)) | G13: =IF(F13="","",IF(F13<TODAY(),"Expired",IF(F13-TODAY()<=30,"Expiring Soon","Valid")))
F14: =IF(E14="","",EDATE(E14,24)) | G14: =IF(F14="","",IF(F14<TODAY(),"Expired",IF(F14-TODAY()<=30,"Expiring Soon","Valid")))
... F102: =IF(E102="","",EDATE(E102,24)) | G102: =IF(F102="","",IF(F102<TODAY(),"Expired",IF(F102-TODAY()<=30,"Expiring Soon","Valid")))

Sheet MS1
A1: MS1 — N95 Fit Test Tracking
A2: Employee Name | B2: Employee ID | C2: Department Email | D2: N95 Mask Type | E2: Fit Test Date | F2: Expiration Date | G2: Validation Status
F3: =IF(E3="","",EDATE(E3,24)) | G3: =IF(F3="","",IF(F3<TODAY(),"Expired",IF(F3-TODAY()<=30,"Expiring Soon","Valid")))
F4: =IF(E4="","",EDATE(E4,24)) | G4: =IF(F4="","",IF(F4<TODAY(),"Expired",IF(F4-TODAY()<=30,"Expiring Soon","Valid")))
F5: =IF(E5="","",EDATE(E5,24)) | G5: =IF(F5="","",IF(F5<TODAY(),"Expired",IF(F5-TODAY()<=30,"Expiring Soon","Valid")))
F6: =IF(E6="","",EDATE(E6,24)) | G6: =IF(F6="","",IF(F6<TODAY(),"Expired",IF(F6-TODAY()<=30,"Expiring Soon","Valid")))
F7: =IF(E7="","",EDATE(E7,24)) | G7: =IF(F7="","",IF(F7<TODAY(),"Expired",IF(F7-TODAY()<=30,"Expiring Soon","Valid")))
F8: =IF(E8="","",EDATE(E8,24)) | G8: =IF(F8="","",IF(F8<TODAY(),"Expired",IF(F8-TODAY()<=30,"Expiring Soon","Valid")))
F9: =IF(E9="","",EDATE(E9,24)) | G9: =IF(F9="","",IF(F9<TODAY(),"Expired",IF(F9-TODAY()<=30,"Expiring Soon","Valid")))
F10: =IF(E10="","",EDATE(E10,24)) | G10: =IF(F10="","",IF(F10<TODAY(),"Expired",IF(F10-TODAY()<=30,"Expiring Soon","Valid")))
F11: =IF(E11="","",EDATE(E11,24)) | G11: =IF(F11="","",IF(F11<TODAY(),"Expired",IF(F11-TODAY()<=30,"Expiring Soon","Valid")))
F12: =IF(E12="","",EDATE(E12,24)) | G12: =IF(F12="","",IF(F12<TODAY(),"Expired",IF(F12-TODAY()<=30,"Expiring Soon","Valid")))
F13: =IF(E13="","",EDATE(E13,24)) | G13: =IF(F13="","",IF(F13<TODAY(),"Expired",IF(F13-TODAY()<=30,"Expiring Soon","Valid")))
F14: =IF(E14="","",EDATE(E14,24)) | G14: =IF(F14="","",IF(F14<TODAY(),"Expired",IF(F14-TODAY()<=30,"Expiring Soon","Valid")))
... F102: =IF(E102="","",EDATE(E102,24)) | G102: =IF(F102="","",IF(F102<TODAY(),"Expired",IF(F102-TODAY()<=30,"Expiring Soon","Valid")))

Sheet DAY CASE
A1: DAY CASE — N95 Fit Test Tracking
A2: Employee Name | B2: Employee ID | C2: Department Email | D2: N95 Mask Type | E2: Fit Test Date | F2: Expiration Date | G2: Validation Status
F3: =IF(E3="","",EDATE(E3,24)) | G3: =IF(F3="","",IF(F3<TODAY(),"Expired",IF(F3-TODAY()<=30,"Expiring Soon","Valid")))
F4: =IF(E4="","",EDATE(E4,24)) | G4: =IF(F4="","",IF(F4<TODAY(),"Expired",IF(F4-TODAY()<=30,"Expiring Soon","Valid")))
F5: =IF(E5="","",EDATE(E5,24)) | G5: =IF(F5="","",IF(F5<TODAY(),"Expired",IF(F5-TODAY()<=30,"Expiring Soon","Valid")))
F6: =IF(E6="","",EDATE(E6,24)) | G6: =IF(F6="","",IF(F6<TODAY(),"Expired",IF(F6-TODAY()<=30,"Expiring Soon","Valid")))
F7: =IF(E7="","",EDATE(E7,24)) | G7: =IF(F7="","",IF(F7<TODAY(),"Expired",IF(F7-TODAY()<=30,"Expiring Soon","Valid")))
F8: =IF(E8="","",EDATE(E8,24)) | G8: =IF(F8="","",IF(F8<TODAY(),"Expired",IF(F8-TODAY()<=30,"Expiring Soon","Valid")))
F9: =IF(E9="","",EDATE(E9,24)) | G9: =IF(F9="","",IF(F9<TODAY(),"Expired",IF(F9-TODAY()<=30,"Expiring Soon","Valid")))
F10: =IF(E10="","",EDATE(E10,24)) | G10: =IF(F10="","",IF(F10<TODAY(),"Expired",IF(F10-TODAY()<=30,"Expiring Soon","Valid")))
F11: =IF(E11="","",EDATE(E11,24)) | G11: =IF(F11="","",IF(F11<TODAY(),"Expired",IF(F11-TODAY()<=30,"Expiring Soon","Valid")))
F12: =IF(E12="","",EDATE(E12,24)) | G12: =IF(F12="","",IF(F12<TODAY(),"Expired",IF(F12-TODAY()<=30,"Expiring Soon","Valid")))
F13: =IF(E13="","",EDATE(E13,24)) | G13: =IF(F13="","",IF(F13<TODAY(),"Expired",IF(F13-TODAY()<=30,"Expiring Soon","Valid")))
F14: =IF(E14="","",EDATE(E14,24)) | G14: =IF(F14="","",IF(F14<TODAY(),"Expired",IF(F14-TODAY()<=30,"Expiring Soon","Valid")))
... F102: =IF(E102="","",EDATE(E102,24)) | G102: =IF(F102="","",IF(F102<TODAY(),"Expired",IF(F102-TODAY()<=30,"Expiring Soon","Valid")))

Sheet LABORATORY
A1: LABORATORY — N95 Fit Test Tracking
A2: Employee Name | B2: Employee ID | C2: Department Email | D2: N95 Mask Type | E2: Fit Test Date | F2: Expiration Date | G2: Validation Status
F3: =IF(E3="","",EDATE(E3,24)) | G3: =IF(F3="","",IF(F3<TODAY(),"Expired",IF(F3-TODAY()<=30,"Expiring Soon","Valid")))
F4: =IF(E4="","",EDATE(E4,24)) | G4: =IF(F4="","",IF(F4<TODAY(),"Expired",IF(F4-TODAY()<=30,"Expiring Soon","Valid")))
F5: =IF(E5="","",EDATE(E5,24)) | G5: =IF(F5="","",IF(F5<TODAY(),"Expired",IF(F5-TODAY()<=30,"Expiring Soon","Valid")))
F6: =IF(E6="","",EDATE(E6,24)) | G6: =IF(F6="","",IF(F6<TODAY(),"Expired",IF(F6-TODAY()<=30,"Expiring Soon","Valid")))
F7: =IF(E7="","",EDATE(E7,24)) | G7: =IF(F7="","",IF(F7<TODAY(),"Expired",IF(F7-TODAY()<=30,"Expiring Soon","Valid")))
F8: =IF(E8="","",EDATE(E8,24)) | G8: =IF(F8="","",IF(F8<TODAY(),"Expired",IF(F8-TODAY()<=30,"Expiring Soon","Valid")))
F9: =IF(E9="","",EDATE(E9,24)) | G9: =IF(F9="","",IF(F9<TODAY(),"Expired",IF(F9-TODAY()<=30,"Expiring Soon","Valid")))
F10: =IF(E10="","",EDATE(E10,24)) | G10: =IF(F10="","",IF(F10<TODAY(),"Expired",IF(F10-TODAY()<=30,"Expiring Soon","Valid")))
F11: =IF(E11="","",EDATE(E11,24)) | G11: =IF(F11="","",IF(F11<TODAY(),"Expired",IF(F11-TODAY()<=30,"Expiring Soon","Valid")))
